Workbook
Name data: I!$B$4:$E$149
Name data: II!$B$4:$E$150
Name data: III!$B$4:$E$146
Name data: IV!$B$5:$E$147
Name data: LKG!$B$4:$E$147
Name data: UKG!$B$4:$E$142
Name data: V!$B$4:$E$148
Name data: VAN!$B$4:$C$150
Name data: VI!$B$4:$E$147
Name data: VII!$B$4:$E$150
Name data: VIII!$B$4:$E$148
Name data: Nur!$B$4:$E$150

Sheet Admission
A1: Admission No. | B1: Admission_date | C1: Admission_Type | D1: Student_Name | E1: Father's_name | F1: Mother's_Name | G1: D.O.B | H1: Class | I1: Aadhar_No. | J1: Calling_No. | K1: Whatsapp_No. | L1: Address | M1: Blood Group | N1: Gender | O1: Status
A2: 1 | B2: 44637 | C2: Hosteller | D2: REHAN SEKH | E2: AZMAL SEKH | F2: HENA BIBI | G2: 40577 | H2: IV | I2: 483830374536 | J2: 9065300299 | L2: RAHASPUR ,PAKUR | N2: Male
A3: 2 | C3: Day Scholar | D3: TAMIM HASAN | E3: SAIFUL SEKH | H3: IV | J3: 9735411842 | N3: Male
A4: 3 | B4: 44644 | C4: Day Scholar | D4: TANISHA NAJ | E4: MD JARRAR HUSSAIN | F4: KAYEMA BIBI | G4: 41642 | H4: I | I4: 678625398221 | J4: 7654919187 | L4: DARIYA PUR ,GUMANI | N4: Female
A5: 4 | B5: 44627 | C5: Hosteller | D5: SAHIL SHEKH | E5: KHALEK SEKH | F5: NAJIFA BIBI | G5: 40951 | H5: IV | I5: 840670678705 | J5: 9955896968 | L5: PAKUR | N5: Male
A6: 5 | C6: Day Scholar | D6: ARHAAN HAQUE | E6: IZAJUL HAQUE | H6: I | J6: 9507760994 | N6: Male
A7: 6 | B7: 44743 | C7: Day Scholar | D7: MD ESHARUL HAQUE | E7: MD MOHAJERUL HAQUE | F7: SAYERA BIBI | G7: 40249 | H7: V | I7: 736274395368 | J7: 9939748660 | K7: 9939748660 | L7: ANDHARKOTA | N7: Male
A8: 7 | B8: 44772 | C8: Hosteller | D8: PARWEJ ISLAM | E8: RAFIKUL ISLAM | F8: RABINA BIBI | G8: 41504 | H8: I | I8: 718294463605 | J8: 9142128216 | K8: 9142128216 | L8: HIRANPUR (pakur) | N8: Male
A9: 8 | B9: 44634 | C9: Hosteller | D9: MD ADIL ANSARI | E9: MD ATAUR RAHMAN ANSARI | G9: 41162 | H9: V | I9: 384628964194 | J9: 9123150068 | K9: 9431776530 | L9: LALMATIYA ,GODDA | N9: Male
A10: 9 | C10: Hosteller | D10: NAGMA TABASSUM | E10: MOJIBUR RAHMAN | H10: VII | J10: 9523145415 | L10: AGLOI | N10: Female
A11: 10 | B11: 44691 | C11: Hosteller | D11: REHAN ALAM | E11: RABIUL ISLAM | F11: JOLENUR BIBI | G11: 41131 | H11: IV | I11: 462714899661 | J11: 9693028244 | N11: Male
A12: 11 | C12: Day Scholar | D12: ABDUL QABEZ | E12: ABDUL QAHAR | H12: IV | J12: 9973967538 | N12: Male
A13: 12 | B13: 44805 | C13: Hosteller | D13: FATEMA ROZI | E13: MD UMED ALI ANSARI | F13: JAHEDA NAAJ | G13: 41384 | H13: IV | I13: 744166970710 | J13: 9643292878 | K13: 9643292878 | L13: BARHET | N13: Female
A14: 13 | B14: 44715 | C14: Hosteller | D14: RASHID JAMAL | E14: IMTEYAZ AHMAD | F14: SAHEBA KHATOON | G14: 41510 | H14: UKG | I14: 790014867935 | J14: 7739447180 | K14: 7739447180 | L14: CHHOTA GANGTI | N14: Male
A15: 14 | B15: 44805 | C15: Hosteller | D15: MD KAISAR PARWEZ | E15: MD UMED ALI ANSARI | F15: JAHEDA NAAJ | G15: 40968 | H15: IV | I15: 715182659764 | J15: 9643292878 | K15: 9643292878 | L15: BARHET | N15: Male
A16: 15 | B16: 44715 | C16: Hosteller | D16: WASI AHAMAD | E16: MD.MUKHTAR ANSARI | F16: ZULEKHA KHATOON | G16: 41821 | H16: UKG | I16: 225538245484 | J16: 8809878555 | K16: 8809878555 | L16: HARINKOL(GODDA) | N16: Male
A17: 16 | B17: 44620 | C17: Hosteller | D17: AYAAN AKHTAR | E17: NASIM AKTAR | F17: TARANNUM RUBY | G17: 42286 | H17: V | I17: 294900296689 | J17: 9430329392 | L17: PANCH KATIYA,BARHET | N17: Male
A18: 17 | B18: 44743 | C18: Hosteller | D18: MERAJ RABBANI | E18: EKRAMUL HOQUE | F18: BEGUM SAJEEDA HOQUE | G18: 40461 | H18: VII | J18: 8521460385 | K18: 8521460385 | L18: DARIYAPUR | N18: Male
A19: 18 | C19: Day Scholar | D19: MD ASIM | E19: SAYEEDUR RAHMAN | F19: NAVERA RAHMAN | H19: III | J19: 9199390869 | N19: Male
A20: 19 | B20: 44634 | C20: Hosteller | D20: SIRAJ AHMAD | E20: KHUSHIRUDDIN SHEKH | G20: 41492 | H20: I | I20: 769234991536 | J20: 9386044411 | K20: 7004550575 | L20: SAGRAMPUR,PAKUR | N20: Male
A21: 20 | C21: Day Scholar | D21: NUSRAT KHATUN | E21: KALAM ANSARI | H21: I | J21: 7667191848 | N21: Female
A22: 21 | C22: Day Scholar | D22: SHAHBAJ ANSARI | E22: KALAM ANSARI | G22: 42327 | H22: UKG | J22: 7667191848 | N22: Male
A23: 22 | C23: Hosteller | D23: MD SAFID | E23: MD SAMSUL HAQUE | H23: UKG | J23: 9955449861 | N23: Male
A24: 23 | B24: 44703 | C24: Hosteller | D24: MD.SAZID ANSARI | E24: MD.SAMSUL HOQUE ANSARI | F24: JAIRUN NISHA | G24: 41402 | H24: IV | I24: 777311579947 | J24: 9955459861 | N24: Male
A25: 24 | B25: 44693 | C25: Day Scholar | D25: AZIZA ASLAMI | E25: ABDUL HAKIM | F25: ESMIRA KHATUN | G25: 42597 | H25: I | J25: 9631552396 | L25: ABDULLAPUR | N25: Female
A26: 25 | B26: 44740 | C26: Day Scholar | D26: AHRAR AHMAD | E26: ABDUL HAKIM | F26: ESMIRA KHATUN | H26: LKG | J26: 9631552396 | K26: 9631552396 | L26: ABDULLAPUR | N26: Male
A27: 26 | B27: 44723 | C27: Day Scholar | D27: NASIB ALAM | E27: SABBIR ALAM | F27: ASNARA KHATUN | G27: 41222 | H27: II | I27: 606211628780 | J27: 7260034191 | K27: 7667144272 | L27: SHRIKUND | N27: Male
A28: 27 | C28: Day Scholar | D28: RUKSAR TABASSUM | E28: BADRUL ISLAM | F28: MUMTAJ BIBI | H28: II | J28: 8340584833 | L28: PURNA PALASBANA | N28: Female
A29: 28 | C29: Hosteller | D29: FAHIM SEKH | E29: KHABIR SEKH | H29: III | J29: 7003238326 | N29: Male
A30: 29 | C30: Hosteller | D30: ASFAK ALAM | E30: SARIFUL HOQUE | H30: II | J30: 8825174593 | N30: Male
A31: 30 | C31: Hosteller | D31: MD REHAN | E31: NASIUR RAHMAN | H31: I | J31: 8969545954 | N31: Male
A32: 31 | B32: 44704 | C32: Hosteller | D32: MALIK ASARI | E32: MD.AMIR HAMJA | F32: RUKSANA BIBI | G32: 41067 | H32: II | I32: 866001943764 | J32: 9771026583 | L32: BARHAIT | N32: Male
A33: 32 | B33: 44704 | C33: Hosteller | D33: IMRAN ANSARI | E33: AMIR HAMZA ANSARI | F33: RUKSANA BIBI | G33: 39878 | H33: V | I33: 493543677435 | J33: 9771026583 | L33: BARHAIT | N33: Male
A34: 33 | C34: Day Scholar | D34: ARMAN IKBAL | E34: ANWAR ALAM | H34: VII | J34: 6201472350 | N34: Male
A35: 34 | B35: 44709 | C35: Hosteller | D35: SAKIB ANSARI | E35: ABDUL GAFFAR ANSARI | F35: HASINA KHATUN | G35: 42193 | H35: LKG | I35: 731849466488 | J35: 9608682077 | K35: 9608682077 | L35: BASDIHA | N35: Male
A36: 35 | B36: 44712 | C36: Day Scholar | D36: ADIL JAMIL | E36: MD.SAGIRUZZAMAN | F36: SHIRI SARMIN | G36: 40822 | H36: IV | I36: 585723050170 | J36: 8434026070 | K36: 9955442128 | L36: ABDULLAHPUR | N36: Male
A37: 36 | B37: 44687 | C37: Day Scholar | D37: TOUHID ALAM | E37: TOFAIL ISLAM | H37: V | I37: 366842848459 | J37: 8340101326 | L37: RAHMATPUR | N37: Male
A38: 37 | C38: Day Scholar | D38: SHAH JISAN | E38: RAFIK ALAM | H38: I | J38: 9955943696 | N38: Male
A39: 38 | B39: 44688 | C39: Hosteller | D39: ZAKE AHMAD MOMIN | E39: ANISUR RAHMAN MOMIN | F39: SHAMIMA KHATUN | H39: UKG | I39: 218062176695 | J39: 9883118912 | N39: Male
A40: 39 | C40: Day Scholar | D40: NAJIJA PARWEEN | E40: HAJIKUL ALAM | H40: VII | J40: 8084078810 | L40: SHRIKUND (GUMANI) | N40: Female
...

Sheet VAN
A1: Total Students | D1: Overall collection | E1: Monthly total fees collection
A2: =COUNT(A4:A366) -> 12 | D2: =SUM(E2:P2) -> 39905 | E2: =SUM(E4:E1002) -> 0 | F2: =SUM(F4:F1002) -> 0 | G2: =SUM(G4:G1002) -> 0 | H2: =SUM(H4:H1002) -> 9000 | I2: =SUM(I4:I1002) -> 10800 | J2: =SUM(J4:J1002) -> 8305 | K2: =SUM(K4:K1002) -> 3800 | L2: =SUM(L4:L1002) -> 2800 | ... P2: =SUM(P4:P1002) -> 800
A3: Ledger_No. | B3: Student_Name | C3: Father's name | D3: Van Fee | E3: Jan | F3: Feb | G3: Mar | H3: Apr | I3: May | J3: Jun | K3: Jul | L3: Aug | M3: Sep | N3: Oct | O3: Nov | P3: Dec
A4: 9 | B4: =IFERROR(VLOOKUP($A4,Admission!$1:$998,4,0),"") -> NAGMA TABASSUM | C4: =IFERROR(VLOOKUP($A4,Admission!$1:$998,5,0),"") -> MOJIBUR RAHMAN | D4: 1000 | E4: 0 | F4: 0 | G4: 0 | H4: 1000 | I4: 1000 | J4: 1000 | K4: 1000 | L4: 1000
A5: 25 | B5: =IFERROR(VLOOKUP($A5,Admission!$1:$998,4,0),"") -> AHRAR AHMAD | C5: =IFERROR(VLOOKUP($A5,Admission!$1:$998,5,0),"") -> ABDUL HAKIM | D5: 1000 | E5: 0 | F5: 0 | G5: 0 | H5: 1000 | I5: 1000
A6: 24 | B6: =IFERROR(VLOOKUP($A6,Admission!$1:$998,4,0),"") -> AZIZA ASLAMI | C6: =IFERROR(VLOOKUP($A6,Admission!$1:$998,5,0),"") -> ABDUL HAKIM | D6: 1000 | E6: 0 | F6: 0 | G6: 0 | H6: 1000 | I6: 1000
A7: 11 | B7: =IFERROR(VLOOKUP($A7,Admission!$1:$998,4,0),"") -> ABDUL QABEZ | C7: =IFERROR(VLOOKUP($A7,Admission!$1:$998,5,0),"") -> ABDUL QAHAR | D7: 1000 | E7: 0 | F7: 0 | G7: 0 | H7: 1000 | I7: 1000 | J7: 1000
A8: 18 | B8: =IFERROR(VLOOKUP($A8,Admission!$1:$998,4,0),"") -> MD ASIM | C8: =IFERROR(VLOOKUP($A8,Admission!$1:$998,5,0),"") -> SAYEEDUR RAHMAN | D8: 1000 | E8: 0 | F8: 0 | G8: 0 | H8: 1000 | I8: 1000 | J8: 1000 | K8: 1000 | L8: 1000 | M8: 1000 | N8: 1000
A9: 35 | B9: =IFERROR(VLOOKUP($A9,Admission!$1:$998,4,0),"") -> ADIL JAMIL | C9: =IFERROR(VLOOKUP($A9,Admission!$1:$998,5,0),"") -> MD.SAGIRUZZAMAN | D9: 1000 | E9: 0 | F9: 0 | G9: 0 | H9: 1000 | I9: 1000 | J9: 1000
A10: 102 | B10: =IFERROR(VLOOKUP($A10,Admission!$1:$998,4,0),"") -> ABYAZ ALAM | C10: =IFERROR(VLOOKUP($A10,Admission!$1:$998,5,0),"") -> MD MULEUDDIN | D10: 800 | E10: 0 | F10: 0 | G10: 0 | H10: 0 | I10: 800 | J10: 800 | K10: 800 | L10: 800 | M10: 800 | N10: 800 | O10: 800 | P10: 800
A11: 122 | B11: =IFERROR(VLOOKUP($A11,Admission!$1:$998,4,0),"") -> RIFFAT PARWEEN | C11: =IFERROR(VLOOKUP($A11,Admission!$1:$998,5,0),"") -> MUNIRUZZAMAN | D11: 1000 | E11: 0 | F11: 0 | G11: 0 | H11: 0 | I11: 1000 | J11: 1000
A12: 157 | B12: =IFERROR(VLOOKUP($A12,Admission!$1:$998,4,0),"") -> ARHAM ASAD | C12: =IFERROR(VLOOKUP($A12,Admission!$1:$998,5,0),"") -> ASADULLAH | D12: 1000 | E12: 0 | F12: 0 | G12: 0 | H12: 1000 | I12: 1000 | J12: 505
A13: 161 | B13: =IFERROR(VLOOKUP($A13,Admission!$1:$998,4,0),"") -> ASIYA PARVEEN | C13: =IFERROR(VLOOKUP($A13,Admission!$1:$998,5,0),"") -> MOJIBUR RAHMAN | D13: 1000 | E13: 0 | F13: 0 | G13: 0 | H13: 1000 | I13: 1000
A14: 58 | B14: =IFERROR(VLOOKUP($A14,Admission!$1:$998,4,0),"") -> ATIF SAMSH | C14: =IFERROR(VLOOKUP($A14,Admission!$1:$998,5,0),"") -> MD SAMSUL HAQUE | D14: 1000 | E14: 0 | F14: 0 | G14: 0 | H14: 0 | I14: 0 | J14: 1000
A15: 171 | B15: =IFERROR(VLOOKUP($A15,Admission!$1:$998,4,0),"") -> MEHNAZ AKHTAR | C15: =IFERROR(VLOOKUP($A15,Admission!$1:$998,5,0),"") -> SHAMIM AKHTAR | D15: 1000 | E15: 0 | F15: 0 | G15: 0 | H15: 1000 | I15: 1000 | J15: 1000 | K15: 1000
B16: =IFERROR(VLOOKUP($A16,Admission!$1:$998,4,0),"") | C16: =IFERROR(VLOOKUP($A16,Admission!$1:$998,5,0),"")
B17: =IFERROR(VLOOKUP($A17,Admission!$1:$998,4,0),"") | C17: =IFERROR(VLOOKUP($A17,Admission!$1:$998,5,0),"")
B18: =IFERROR(VLOOKUP($A18,Admission!$1:$998,4,0),"") | C18: =IFERROR(VLOOKUP($A18,Admission!$1:$998,5,0),"")
B19: =IFERROR(VLOOKUP($A19,Admission!$1:$998,4,0),"") | C19: =IFERROR(VLOOKUP($A19,Admission!$1:$998,5,0),"")
B20: =IFERROR(VLOOKUP($A20,Admission!$1:$998,4,0),"") | C20: =IFERROR(VLOOKUP($A20,Admission!$1:$998,5,0),"")
B21: =IFERROR(VLOOKUP($A21,Admission!$1:$998,4,0),"") | C21: =IFERROR(VLOOKUP($A21,Admission!$1:$998,5,0),"")
B22: =IFERROR(VLOOKUP($A22,Admission!$1:$998,4,0),"") | C22: =IFERROR(VLOOKUP($A22,Admission!$1:$998,5,0),"")
B23: =IFERROR(VLOOKUP($A23,Admission!$1:$998,4,0),"") | C23: =IFERROR(VLOOKUP($A23,Admission!$1:$998,5,0),"")
B24: =IFERROR(VLOOKUP($A24,Admission!$1:$998,4,0),"") | C24: =IFERROR(VLOOKUP($A24,Admission!$1:$998,5,0),"")
B25: =IFERROR(VLOOKUP($A25,Admission!$1:$998,4,0),"") | C25: =IFERROR(VLOOKUP($A25,Admission!$1:$998,5,0),"")
B26: =IFERROR(VLOOKUP($A26,Admission!$1:$998,4,0),"") | C26: =IFERROR(VLOOKUP($A26,Admission!$1:$998,5,0),"")
B27: =IFERROR(VLOOKUP($A27,Admission!$1:$998,4,0),"") | C27: =IFERROR(VLOOKUP($A27,Admission!$1:$998,5,0),"")
... B150: =IFERROR(VLOOKUP($A150,Admission!$1:$998,4,0),"") | C150: =IFERROR(VLOOKUP($A150,Admission!$1:$998,5,0),"")

Sheet Nur
A1: Total Students | B1: Hosteller | C1: Day Scholar | E1: Overall Collection | F1: Monthly total fees collection
A2: =COUNT(A4:A366) -> 11 | B2: =COUNTIF($E$4:$E$192,B1) -> 2 | C2: =COUNTIF($E$4:$E$192,C1) -> 9 | E2: =SUM(F2:U2) -> 125000 | F2: =SUM(F$4:F$1002) -> 4900 | G2: =SUM(G$4:G$1002) -> 6100 | H2: =SUM(H$4:H$1002) -> 6700 | I2: =SUM(I4:I10) -> 1000 | J2: =SUM(J$4:J$1002) -> 6700 | K2: =SUM(K$4:K$1002) -> 11600 | L2: =SUM(L$4:L$1002) -> 12800 | M2: =SUM(M$4:M$1002) -> 1800 | N2: =SUM(N$4:N$1002) -> 12200 | O2: =SUM(O$4:O$1002) -> 12200 | P2: =SUM(P$4:P$1002) -> 12200 | Q2: =SUM(Q$4:Q$1002) -> 1600 | ... U2: =SUM(U$4:U$1002) -> 11000
A3: Ledger_No. | B3: Student_Name | C3: Father's name | D3: Phone No: | E3: Admission_Type | F3: Apr | G3: May | H3: Jun | I3: Exam | J3: Jul | K3: Aug | L3: Sep | M3: Exam Fee | N3: Oct | O3: Nov | P3: Dec | Q3: Exam Fee | R3: Jan | S3: Feb | T3: Exam Fee | U3: Mar
A4: 78 | B4: =IFERROR(VLOOKUP($A4,Admission!$1:$998,4,0),"") -> DARAKSHA PARVIN | C4: =IFERROR(VLOOKUP($A4,Admission!$1:$998,5,0),"") -> TASKIL AHMAD | D4: =IFERROR(VLOOKUP($A4,Admission!$1:$998,10,0),"") -> 7033666624 | E4: =IFERROR(VLOOKUP($A4,Admission!$1:$998,3,0),"") -> Day Scholar | F4: 600 | G4: 600 | H4: 600 | I4: 200 | J4: 600 | K4: 600 | L4: 600 | M4: 200 | N4: 600 | O4: 600 | P4: 600 | Q4: 200 | R4: 600 | S4: 600 | T4: 200 | U4: 600
A5: 82 | B5: =IFERROR(VLOOKUP($A5,Admission!$1:$998,4,0),"") -> ASIF AHMAD | C5: =IFERROR(VLOOKUP($A5,Admission!$1:$998,5,0),"") -> MD MUKHTAR ANSARI | D5: =IFERROR(VLOOKUP($A5,Admission!$1:$998,10,0),"") -> 8809878555 | E5: =IFERROR(VLOOKUP($A5,Admission!$1:$998,3,0),"") -> Hosteller | F5: 3700 | G5: 3700 | H5: 3700 | I5: 200 | J5: 3700 | K5: 3700 | L5: 3700 | M5: 200 | N5: 3700 | O5: 3700 | P5: 3700 | Q5: 200 | R5: 3700 | S5: 3700 | T5: 200 | U5: 3700
A6: 84 | B6: =IFERROR(VLOOKUP($A6,Admission!$1:$998,4,0),"") -> ESMA NAAJ | C6: =IFERROR(VLOOKUP($A6,Admission!$1:$998,5,0),"") -> ANIKUL ISLAM | D6: =IFERROR(VLOOKUP($A6,Admission!$1:$998,10,0),"") -> 9064803071 | E6: =IFERROR(VLOOKUP($A6,Admission!$1:$998,3,0),"") -> Day Scholar | F6: 600 | G6: 600 | H6: 600 | I6: 200 | J6: 600 | K6: 600 | L6: 600 | M6: 200 | N6: 600 | O6: 600 | P6: 600 | Q6: 200 | R6: 600 | S6: 600 | T6: 200 | U6: 600
A7: 105 | B7: =IFERROR(VLOOKUP($A7,Admission!$1:$998,4,0),"") -> IMRANA HASAN | C7: =IFERROR(VLOOKUP($A7,Admission!$1:$998,5,0),"") -> MD RELIM SHEKH | D7: =IFERROR(VLOOKUP($A7,Admission!$1:$998,10,0),"") -> 7070636161 | E7: =IFERROR(VLOOKUP($A7,Admission!$1:$998,3,0),"") -> Day Scholar | F7: 0 | G7: 600 | H7: 600 | I7: 200 | J7: 600 | K7: 600 | L7: 600 | M7: 200
A8: 137 | B8: =IFERROR(VLOOKUP($A8,Admission!$1:$998,4,0),"") -> ADEEB IMTIYAZ | C8: =IFERROR(VLOOKUP($A8,Admission!$1:$998,5,0),"") -> IMTIYAZ ALAM | D8: =IFERROR(VLOOKUP($A8,Admission!$1:$998,10,0),"") -> 9567188032 | E8: =IFERROR(VLOOKUP($A8,Admission!$1:$998,3,0),"") -> Day Scholar | F8: 0 | G8: 600 | H8: 600 | J8: 600 | K8: 600 | L8: 600 | N8: 600 | O8: 600 | P8: 600
A9: 143 | B9: =IFERROR(VLOOKUP($A9,Admission!$1:$998,4,0),"") -> SAHA ALAM | C9: =IFERROR(VLOOKUP($A9,Admission!$1:$998,5,0),"") -> MD SAMIR SHEKH | D9: =IFERROR(VLOOKUP($A9,Admission!$1:$998,10,0),"") -> 6260898588 | E9: =IFERROR(VLOOKUP($A9,Admission!$1:$998,3,0),"") -> Day Scholar | F9: 0 | G9: 0 | H9: 600 | I9: 200 | J9: 600 | K9: 600 | L9: 600 | M9: 200 | N9: 600 | O9: 600 | P9: 600 | Q9: 200 | R9: 600 | S9: 600 | T9: 200 | U9: 600
B10: =IFERROR(VLOOKUP($A10,Admission!$1:$998,4,0),"") | C10: =IFERROR(VLOOKUP($A10,Admission!$1:$998,5,0),"") | D10: =IFERROR(VLOOKUP($A10,Admission!$1:$998,10,0),"") | E10: =IFERROR(VLOOKUP($A10,Admission!$1:$998,3,0),"")
B11: =IFERROR(VLOOKUP($A11,Admission!$1:$998,4,0),"") | C11: =IFERROR(VLOOKUP($A11,Admission!$1:$998,5,0),"") | D11: =IFERROR(VLOOKUP($A11,Admission!$1:$998,10,0),"") | E11: =IFERROR(VLOOKUP($A11,Admission!$1:$998,3,0),"")
A12: 178 | B12: =IFERROR(VLOOKUP($A12,Admission!$1:$998,4,0),"") -> IZHAAN ADEEB | C12: =IFERROR(VLOOKUP($A12,Admission!$1:$998,5,0),"") -> KAIFUL ISLAM | D12: =IFERROR(VLOOKUP($A12,Admission!$1:$998,10,0),"") -> 7033873731 | E12: =IFERROR(VLOOKUP($A12,Admission!$1:$998,3,0),"") -> Day Scholar | F12: 0 | G12: 0 | H12: 0 | I12: 0 | J12: 0 | K12: 600 | L12: 600 | N12: 600 | O12: 600 | P12: 600 | R12: 600
A13: 179 | B13: =IFERROR(VLOOKUP($A13,Admission!$1:$998,4,0),"") -> FARHAN HAIDER | C13: =IFERROR(VLOOKUP($A13,Admission!$1:$998,5,0),"") -> GULAM HAIDER MANSUNI | D13: =IFERROR(VLOOKUP($A13,Admission!$1:$998,10,0),"") -> 9661404057 | E13: =IFERROR(VLOOKUP($A13,Admission!$1:$998,3,0),"") -> Day Scholar | F13: 0 | G13: 0 | H13: 0 | I13: 0 | J13: 0 | K13: 600 | L13: 600 | M13: 200 | N13: 600 | O13: 600 | P13: 600 | Q13: 200 | R13: 600 | S13: 600 | T13: 200 | U13: 600
A14: 181 | B14: =IFERROR(VLOOKUP($A14,Admission!$1:$998,4,0),"") -> MUSARAAF ANSARI | C14: =IFERROR(VLOOKUP($A14,Admission!$1:$998,5,0),"") -> MANIRUL ANSARI | D14: =IFERROR(VLOOKUP($A14,Admission!$1:$998,10,0),"") -> 6200383504 | E14: =IFERROR(VLOOKUP($A14,Admission!$1:$998,3,0),"") -> Hosteller | F14: 0 | G14: 0 | H14: 0 | I14: 0 | J14: 0 | K14: 3700 | L14: 3700 | M14: 200 | N14: 3700 | O14: 3700 | P14: 3700 | Q14: 200 | R14: 3700 | S14: 3700 | T14: 200 | U14: 3700
A15: 182 | B15: =IFERROR(VLOOKUP($A15,Admission!$1:$998,4,0),"") -> RAHNUMA TANJIR | C15: =IFERROR(VLOOKUP($A15,Admission!$1:$998,5,0),"") -> MD TANJIRUL SHAIKH | D15: =IFERROR(VLOOKUP($A15,Admission!$1:$998,10,0),"") -> 8569061769 | E15: =IFERROR(VLOOKUP($A15,Admission!$1:$998,3,0),"") -> Day Scholar | F15: 0 | G15: 0 | H15: 0 | I15: 0 | J15: 0 | K15: 0 | L15: 600 | M15: 200 | N15: 600 | O15: 600 | P15: 600 | Q15: 200 | R15: 600 | S15: 600 | T15: 200 | U15: 600
A16: 183 | B16: =IFERROR(VLOOKUP($A16,Admission!$1:$998,4,0),"") -> MINSHA PARVEEN | C16: =IFERROR(VLOOKUP($A16,Admission!$1:$998,5,0),"") -> ASHRUDDIN ALAM | D16: =IFERROR(VLOOKUP($A16,Admission!$1:$998,10,0),"") -> 6207575260 | E16: =IFERROR(VLOOKUP($A16,Admission!$1:$998,3,0),"") -> Day Scholar | F16: 0 | G16: 0 | H16: 0 | I16: 0 | J16: 0 | K16: 0 | L16: 600 | M16: 200 | N16: 600 | O16: 600 | P16: 600 | Q16: 200 | R16: 600 | S16: 600 | T16: 200 | U16: 600
B17: =IFERROR(VLOOKUP($A17,Admission!$1:$998,4,0),"") | C17: =IFERROR(VLOOKUP($A17,Admission!$1:$998,5,0),"") | D17: =IFERROR(VLOOKUP($A17,Admission!$1:$998,10,0),"") | E17: =IFERROR(VLOOKUP($A17,Admission!$1:$998,3,0),"")
B18: =IFERROR(VLOOKUP($A18,Admission!$1:$998,4,0),"") | C18: =IFERROR(VLOOKUP($A18,Admission!$1:$998,5,0),"") | D18: =IFERROR(VLOOKUP($A18,Admission!$1:$998,10,0),"") | E18: =IFERROR(VLOOKUP($A18,Admission!$1:$998,3,0),"")
B19: =IFERROR(VLOOKUP($A19,Admission!$1:$998,4,0),"") | C19: =IFERROR(VLOOKUP($A19,Admission!$1:$998,5,0),"") | D19: =IFERROR(VLOOKUP($A19,Admission!$1:$998,10,0),"") | E19: =IFERROR(VLOOKUP($A19,Admission!$1:$998,3,0),"")
B20: =IFERROR(VLOOKUP($A20,Admission!$1:$998,4,0),"") | C20: =IFERROR(VLOOKUP($A20,Admission!$1:$998,5,0),"") | D20: =IFERROR(VLOOKUP($A20,Admission!$1:$998,10,0),"") | E20: =IFERROR(VLOOKUP($A20,Admission!$1:$998,3,0),"")
B21: =IFERROR(VLOOKUP($A21,Admission!$1:$998,4,0),"") | C21: =IFERROR(VLOOKUP($A21,Admission!$1:$998,5,0),"") | D21: =IFERROR(VLOOKUP($A21,Admission!$1:$998,10,0),"") | E21: =IFERROR(VLOOKUP($A21,Admission!$1:$998,3,0),"")
B22: =IFERROR(VLOOKUP($A22,Admission!$1:$998,4,0),"") | C22: =IFERROR(VLOOKUP($A22,Admission!$1:$998,5,0),"") | D22: =IFERROR(VLOOKUP($A22,Admission!$1:$998,10,0),"") | E22: =IFERROR(VLOOKUP($A22,Admission!$1:$998,3,0),"")
B23: =IFERROR(VLOOKUP($A23,Admission!$1:$998,4,0),"") | C23: =IFERROR(VLOOKUP($A23,Admission!$1:$998,5,0),"") | D23: =IFERROR(VLOOKUP($A23,Admission!$1:$998,10,0),"") | E23: =IFERROR(VLOOKUP($A23,Admission!$1:$998,3,0),"")
B24: =IFERROR(VLOOKUP($A24,Admission!$1:$998,4,0),"") | C24: =IFERROR(VLOOKUP($A24,Admission!$1:$998,5,0),"") | D24: =IFERROR(VLOOKUP($A24,Admission!$1:$998,10,0),"") | E24: =IFERROR(VLOOKUP($A24,Admission!$1:$998,3,0),"")
B25: =IFERROR(VLOOKUP($A25,Admission!$1:$998,4,0),"") | C25: =IFERROR(VLOOKUP($A25,Admission!$1:$998,5,0),"") | D25: =IFERROR(VLOOKUP($A25,Admission!$1:$998,10,0),"") | E25: =IFERROR(VLOOKUP($A25,Admission!$1:$998,3,0),"")
B26: =IFERROR(VLOOKUP($A26,Admission!$1:$998,4,0),"") | C26: =IFERROR(VLOOKUP($A26,Admission!$1:$998,5,0),"") | D26: =IFERROR(VLOOKUP($A26,Admission!$1:$998,10,0),"") | E26: =IFERROR(VLOOKUP($A26,Admission!$1:$998,3,0),"")
B27: =IFERROR(VLOOKUP($A27,Admission!$1:$998,4,0),"") | C27: =IFERROR(VLOOKUP($A27,Admission!$1:$998,5,0),"") | D27: =IFERROR(VLOOKUP($A27,Admission!$1:$998,10,0),"") | E27: =IFERROR(VLOOKUP($A27,Admission!$1:$998,3,0),"")
B28: =IFERROR(VLOOKUP($A28,Admission!$1:$998,4,0),"") | C28: =IFERROR(VLOOKUP($A28,Admission!$1:$998,5,0),"") | D28: =IFERROR(VLOOKUP($A28,Admission!$1:$998,10,0),"") | E28: =IFERROR(VLOOKUP($A28,Admission!$1:$998,3,0),"")
... B150: =IFERROR(VLOOKUP($A150,Admission!$1:$998,4,0),"") | C150: =IFERROR(VLOOKUP($A150,Admission!$1:$998,5,0),"") | D150: =IFERROR(VLOOKUP($A150,Admission!$1:$998,10,0),"") | E150: =IFERROR(VLOOKUP($A150,Admission!$1:$998,3,0),"")
E151: =IFERROR(VLOOKUP($A151,Admission!150:1145,3,0),"")
E152: =IFERROR(VLOOKUP($A152,Admission!151:1146,3,0),"")
E153: =IFERROR(VLOOKUP($A153,Admission!152:1147,3,0),"")
E154: =IFERROR(VLOOKUP($A154,Admission!153:1148,3,0),"")
E155: =IFERROR(VLOOKUP($A155,Admission!154:1149,3,0),"")
E156: =IFERROR(VLOOKUP($A156,Admission!155:1150,3,0),"")
E157: =IFERROR(VLOOKUP($A157,Admission!156:1151,3,0),"")
E158: =IFERROR(VLOOKUP($A158,Admission!157:1152,3,0),"")
E159: =IFERROR(VLOOKUP($A159,Admission!158:1153,3,0),"")
E160: =IFERROR(VLOOKUP($A160,Admission!159:1154,3,0),"")
E161: =IFERROR(VLOOKUP($A161,Admission!160:1155,3,0),"")
...

Sheet LKG
A1: z | B1: Hosteller | C1: Day Scholar | E1: Overall Collection | F1: Monthly total fees collection
A2: =COUNT(A4:A363) -> 13 | B2: =COUNTIF($E$4:$E$189,B1) -> 8 | C2: =COUNTIF($E$4:$E$189,C1) -> 5 | E2: =SUM(F2:U2) -> 360752 | F2: =SUM(F$4:F$1000) -> 16000 | G2: =SUM(G$4:G$1000) -> 21500 | H2: =SUM(H4:H16) -> 1500 | I2: =SUM(I$4:I$1000) -> 32000 | J2: =SUM(J$4:J$1000) -> 32000 | K2: =SUM(K$4:K$1000) -> 31000 | L2: =SUM(L$4:L$1000) -> 32000 | M2: =SUM(M$4:M$1000) -> 1500 | N2: =SUM(N$4:N$1000) -> 32000 | O2: =SUM(O$4:O$1000) -> 32000 | P2: =SUM(P$4:P$1000) -> 32000 | ... U2: =SUM(U$4:U$1000) -> 31402
A3: Ledger_No. | B3: Student_Name | C3: Father's name | D3: Phone No: | E3: Admission_Type | F3: Apr | G3: May | I3: Jun | J3: Jul | K3: Aug | L3: Sep | M3: Exam Fee | N3: Oct | O3: Nov | P3: Dec | Q3: Exam Fee | R3: Jan | S3: Feb | T3: Exam Fee | U3: Mar
A4: 25 | B4: =IFERROR(VLOOKUP($A4,Admission!$1:$998,4,0),"") -> AHRAR AHMAD | C4: =IFERROR(VLOOKUP($A4,Admission!$1:$998,5,0),"") -> ABDUL HAKIM | D4: =IFERROR(VLOOKUP($A4,Admission!$1:$998,10,0),"") -> 9631552396 | E4: =IFERROR(VLOOKUP($A4,Admission!$1:$998,3,0),"") -> Day Scholar | F4: 600 | G4: 600 | H4: 200 | I4: 600 | J4: 600 | K4: 600 | L4: 600 | M4: 200 | N4: 600 | O4: 600 | P4: 600 | Q4: 200 | R4: 600 | S4: 600 | T4: 200 | U4: 600
A5: 118 | B5: =IFERROR(VLOOKUP($A5,Admission!$1:$998,4,0),"") -> SAJID AKHTAR | C5: =IFERROR(VLOOKUP($A5,Admission!$1:$998,5,0),"") -> MD ZIYAUR RAHMAN | D5: =IFERROR(VLOOKUP($A5,Admission!$1:$998,10,0),"") -> 9199391535 | E5: =IFERROR(VLOOKUP($A5,Admission!$1:$998,3,0),"") -> Hosteller | F5: 0 | G5: 600 | H5: 150 | I5: 3700 | J5: 3700 | K5: 3700 | L5: 3700 | M5: 150 | N5: 3700 | O5: 3700 | P5: 3700 | R5: 3700 | S5: 3700 | U5: 3700
A6: 34 | B6: =IFERROR(VLOOKUP($A6,Admission!$1:$998,4,0),"") -> SAKIB ANSARI | C6: =IFERROR(VLOOKUP($A6,Admission!$1:$998,5,0),"") -> ABDUL GAFFAR ANSARI | D6: =IFERROR(VLOOKUP($A6,Admission!$1:$998,10,0),"") -> 9608682077 | E6: =IFERROR(VLOOKUP($A6,Admission!$1:$998,3,0),"") -> Hosteller | F6: 3700 | G6: 3700 | H6: 150 | I6: 3700 | J6: 3700 | K6: 3700 | L6: 3700 | M6: 150 | N6: 3700 | O6: 3700 | P6: 3700 | Q6: 150 | R6: 3700 | S6: 3700 | T6: 150 | U6: 3700
A7: 56 | B7: =IFERROR(VLOOKUP($A7,Admission!$1:$998,4,0),"") -> NAFISH IKBAL | C7: =IFERROR(VLOOKUP($A7,Admission!$1:$998,5,0),"") -> AKMAL HUSSAIN | D7: =IFERROR(VLOOKUP($A7,Admission!$1:$998,10,0),"") -> 9507632035 | E7: =IFERROR(VLOOKUP($A7,Admission!$1:$998,3,0),"") -> Hosteller | F7: 3700 | G7: 3700 | H7: 150 | I7: 3700 | J7: 3700 | K7: 3700 | L7: 3700 | M7: 150 | N7: 3700 | O7: 3700 | P7: 3700 | Q7: 150 | R7: 3700 | S7: 3700 | T7: 150 | U7: 3700
A8: 7 | B8: =IFERROR(VLOOKUP($A8,Admission!$1:$998,4,0),"") -> PARWEJ ISLAM | C8: =IFERROR(VLOOKUP($A8,Admission!$1:$998,5,0),"") -> RAFIKUL ISLAM | D8: =IFERROR(VLOOKUP($A8,Admission!$1:$998,10,0),"") -> 9142128216 | E8: =IFERROR(VLOOKUP($A8,Admission!$1:$998,3,0),"") -> Hosteller | F8: 3700 | G8: 3700 | H8: 150 | I8: 3700 | J8: 3700 | K8: 3700 | L8: 3700 | N8: 3700 | O8: 3700 | P8: 3700 | R8: 3700 | S8: 3700 | U8: 3700
A9: 74 | B9: =IFERROR(VLOOKUP($A9,Admission!$1:$998,4,0),"") -> MOHAMMAD AYAAN ANSARI | C9: =IFERROR(VLOOKUP($A9,Admission!$1:$998,5,0),"") -> MOHAMMAD JIYAUL ANSARI | D9: =IFERROR(VLOOKUP($A9,Admission!$1:$998,10,0),"") -> 8809023587 | E9: =IFERROR(VLOOKUP($A9,Admission!$1:$998,3,0),"") -> Hosteller | F9: 3700 | G9: 3700 | H9: 150 | I9: 3700 | J9: 3700 | K9: 3700 | L9: 3700 | M9: 150 | N9: 3700 | O9: 3700 | P9: 3700 | Q9: 150 | R9: 3700 | S9: 3700 | U9: 3700
A10: 96 | B10: =IFERROR(VLOOKUP($A10,Admission!$1:$998,4,0),"") -> AHAD ANSARI | C10: =IFERROR(VLOOKUP($A10,Admission!$1:$998,5,0),"") -> TAIMUR ANSARI | D10: =IFERROR(VLOOKUP($A10,Admission!$1:$998,10,0),"") -> 9708627203 | E10: =IFERROR(VLOOKUP($A10,Admission!$1:$998,3,0),"") -> Day Scholar | F10: 0 | G10: 600 | I10: 600 | J10: 600 | K10: 600 | L10: 600 | M10: 150 | N10: 600 | O10: 600 | P10: 600 | Q10: 150 | R10: 600 | S10: 600 | T10: 150 | U10: 600
A11: 102 | B11: =IFERROR(VLOOKUP($A11,Admission!$1:$998,4,0),"") -> ABYAZ ALAM | C11: =IFERROR(VLOOKUP($A11,Admission!$1:$998,5,0),"") -> MD MULEUDDIN | D11: =IFERROR(VLOOKUP($A11,Admission!$1:$998,10,0),"") -> 6205109895 | E11: =IFERROR(VLOOKUP($A11,Admission!$1:$998,3,0),"") -> Day Scholar | F11: 0 | G11: 600 | H11: 200 | I11: 600 | J11: 600 | K11: 600 | L11: 600 | M11: 150 | N11: 600 | O11: 600 | P11: 600 | Q11: 200 | R11: 600
A12: 113 | B12: =IFERROR(VLOOKUP($A12,Admission!$1:$998,4,0),"") -> MD HUSEL NABIL | C12: =IFERROR(VLOOKUP($A12,Admission!$1:$998,5,0),"") -> MD AMJAD ANSARI | D12: =IFERROR(VLOOKUP($A12,Admission!$1:$998,10,0),"") -> 9771026503 | E12: =IFERROR(VLOOKUP($A12,Admission!$1:$998,3,0),"") -> Hosteller | F12: 0 | G12: 3700 | H12: 200 | I12: 3700 | J12: 3700 | K12: 3700 | L12: 3700 | M12: 200 | N12: 3700 | O12: 3700 | P12: 3700 | Q12: 200 | R12: 3700 | S12: 3700 | T12: 200 | U12: 3700
A13: 120 | B13: =IFERROR(VLOOKUP($A13,Admission!$1:$998,4,0),"") -> MD FAHIM | C13: =IFERROR(VLOOKUP($A13,Admission!$1:$998,5,0),"") -> ABDUL HAMID ANSARI | D13: =IFERROR(VLOOKUP($A13,Admission!$1:$998,10,0),"") -> 9835842208 | E13: =IFERROR(VLOOKUP($A13,Admission!$1:$998,3,0),"") -> Hosteller | F13: 0 | G13: 0 | I13: 3700 | J13: 3700 | K13: 2700 | L13: 3700 | N13: 3700 | O13: 3700 | P13: 3700 | R13: 3700 | S13: 3700 | U13: 3700
A14: 156 | B14: =IFERROR(VLOOKUP($A14,Admission!$1:$998,4,0),"") -> NIYAZ AHMAD | C14: =IFERROR(VLOOKUP($A14,Admission!$1:$998,5,0),"") -> MD SELIM | D14: =IFERROR(VLOOKUP($A14,Admission!$1:$998,10,0),"") -> 8789734647 | E14: =IFERROR(VLOOKUP($A14,Admission!$1:$998,3,0),"") -> Day Scholar | F14: 600 | G14: 600 | H14: 150 | I14: 600 | J14: 600 | K14: 600 | L14: 600 | M14: 200 | N14: 600 | O14: 600 | P14: 600 | Q14: 200 | R14: 600 | S14: 600 | T14: 200 | U14: 600
A15: 157 | B15: =IFERROR(VLOOKUP($A15,Admission!$1:$998,4,0),"") -> ARHAM ASAD | C15: =IFERROR(VLOOKUP($A15,Admission!$1:$998,5,0),"") -> ASADULLAH | D15: =IFERROR(VLOOKUP($A15,Admission!$1:$998,10,0),"") -> 9955016677 | E15: =IFERROR(VLOOKUP($A15,Admission!$1:$998,3,0),"") -> Day Scholar | F15: free | G15: free | H15: free | I15: free | J15: free | K15: free | L15: free | M15: free | N15: free | O15: free | P15: free | Q15: free | R15: free | S15: free | T15: free | U15: 2
A16: 166 | B16: TAMIM IKBAL | C16: =IFERROR(VLOOKUP($A16,Admission!$1:$998,5,0),"") -> JAUHAR ALAM | D16: =IFERROR(VLOOKUP($A16,Admission!$1:$998,10,0),"") -> 9304562957 | E16: =IFERROR(VLOOKUP($A16,Admission!$1:$998,3,0),"") -> Hosteller | F16: 0 | G16: 0 | H16: 0 | I16: 3700 | J16: 3700 | K16: 3700 | L16: 3700 | N16: 3700 | O16: 3700 | P16: 3700 | R16: 3700 | S16: 3700 | U16: 3700
B17: =IFERROR(VLOOKUP($A17,Admission!$1:$998,4,0),"") | C17: =IFERROR(VLOOKUP($A17,Admission!$1:$998,5,0),"") | D17: =IFERROR(VLOOKUP($A17,Admission!$1:$998,10,0),"") | E17: =IFERROR(VLOOKUP($A17,Admission!$1:$998,3,0),"")
B18: =IFERROR(VLOOKUP($A18,Admission!$1:$998,4,0),"") | C18: =IFERROR(VLOOKUP($A18,Admission!$1:$998,5,0),"") | D18: =IFERROR(VLOOKUP($A18,Admission!$1:$998,10,0),"") | E18: =IFERROR(VLOOKUP($A18,Admission!$1:$998,3,0),"")
B19: =IFERROR(VLOOKUP($A19,Admission!$1:$998,4,0),"") | C19: =IFERROR(VLOOKUP($A19,Admission!$1:$998,5,0),"") | D19: =IFERROR(VLOOKUP($A19,Admission!$1:$998,10,0),"") | E19: =IFERROR(VLOOKUP($A19,Admission!$1:$998,3,0),"")
B20: =IFERROR(VLOOKUP($A20,Admission!$1:$998,4,0),"") | C20: =IFERROR(VLOOKUP($A20,Admission!$1:$998,5,0),"") | D20: =IFERROR(VLOOKUP($A20,Admission!$1:$998,10,0),"") | E20: =IFERROR(VLOOKUP($A20,Admission!$1:$998,3,0),"")
B21: =IFERROR(VLOOKUP($A21,Admission!$1:$998,4,0),"") | C21: =IFERROR(VLOOKUP($A21,Admission!$1:$998,5,0),"") | D21: =IFERROR(VLOOKUP($A21,Admission!$1:$998,10,0),"") | E21: =IFERROR(VLOOKUP($A21,Admission!$1:$998,3,0),"")
B22: =IFERROR(VLOOKUP($A22,Admission!$1:$998,4,0),"") | C22: =IFERROR(VLOOKUP($A22,Admission!$1:$998,5,0),"") | D22: =IFERROR(VLOOKUP($A22,Admission!$1:$998,10,0),"") | E22: =IFERROR(VLOOKUP($A22,Admission!$1:$998,3,0),"")
B23: =IFERROR(VLOOKUP($A23,Admission!$1:$998,4,0),"") | C23: =IFERROR(VLOOKUP($A23,Admission!$1:$998,5,0),"") | D23: =IFERROR(VLOOKUP($A23,Admission!$1:$998,10,0),"") | E23: =IFERROR(VLOOKUP($A23,Admission!$1:$998,3,0),"")
B24: =IFERROR(VLOOKUP($A24,Admission!$1:$998,4,0),"") | C24: =IFERROR(VLOOKUP($A24,Admission!$1:$998,5,0),"") | D24: =IFERROR(VLOOKUP($A24,Admission!$1:$998,10,0),"") | E24: =IFERROR(VLOOKUP($A24,Admission!$1:$998,3,0),"")
B25: =IFERROR(VLOOKUP($A25,Admission!$1:$998,4,0),"") | C25: =IFERROR(VLOOKUP($A25,Admission!$1:$998,5,0),"") | D25: =IFERROR(VLOOKUP($A25,Admission!$1:$998,10,0),"") | E25: =IFERROR(VLOOKUP($A25,Admission!$1:$998,3,0),"")
B26: =IFERROR(VLOOKUP($A26,Admission!$1:$998,4,0),"") | C26: =IFERROR(VLOOKUP($A26,Admission!$1:$998,5,0),"") | D26: =IFERROR(VLOOKUP($A26,Admission!$1:$998,10,0),"") | E26: =IFERROR(VLOOKUP($A26,Admission!$1:$998,3,0),"")
B27: =IFERROR(VLOOKUP($A27,Admission!$1:$998,4,0),"") | C27: =IFERROR(VLOOKUP($A27,Admission!$1:$998,5,0),"") | D27: =IFERROR(VLOOKUP($A27,Admission!$1:$998,10,0),"") | E27: =IFERROR(VLOOKUP($A27,Admission!$1:$998,3,0),"")
B28: =IFERROR(VLOOKUP($A28,Admission!$1:$998,4,0),"") | C28: =IFERROR(VLOOKUP($A28,Admission!$1:$998,5,0),"") | D28: =IFERROR(VLOOKUP($A28,Admission!$1:$998,10,0),"") | E28: =IFERROR(VLOOKUP($A28,Admission!$1:$998,3,0),"")
... B50: =IFERROR(VLOOKUP($A50,Admission!$1:$998,4,0),"") | C50: =IFERROR(VLOOKUP($A50,Admission!$1:$998,5,0),"") | D50: =IFERROR(VLOOKUP($A50,Admission!$1:$998,10,0),"") | E50: =IFERROR(VLOOKUP($A50,Admission!$1:$998,3,0),"")
B51: =IFERROR(VLOOKUP($A51,Admission!$1:$998,4,0),"") | C51: =IFERROR(VLOOKUP($A51,Admission!$1:$998,5,0),"") | E51: =IFERROR(VLOOKUP($A51,Admission!$1:$998,3,0),"")
B52: =IFERROR(VLOOKUP($A52,Admission!$1:$998,4,0),"") | C52: =IFERROR(VLOOKUP($A52,Admission!$1:$998,5,0),"") | E52: =IFERROR(VLOOKUP($A52,Admission!$1:$998,3,0),"")
B53: =IFERROR(VLOOKUP($A53,Admission!$1:$998,4,0),"") | C53: =IFERROR(VLOOKUP($A53,Admission!$1:$998,5,0),"") | E53: =IFERROR(VLOOKUP($A53,Admission!$1:$998,3,0),"")
B54: =IFERROR(VLOOKUP($A54,Admission!$1:$998,4,0),"") | C54: =IFERROR(VLOOKUP($A54,Admission!$1:$998,5,0),"") | E54: =IFERROR(VLOOKUP($A54,Admission!$1:$998,3,0),"")
B55: =IFERROR(VLOOKUP($A55,Admission!$1:$998,4,0),"") | C55: =IFERROR(VLOOKUP($A55,Admission!$1:$998,5,0),"") | E55: =IFERROR(VLOOKUP($A55,Admission!$1:$998,3,0),"")
B56: =IFERROR(VLOOKUP($A56,Admission!$1:$998,4,0),"") | C56: =IFERROR(VLOOKUP($A56,Admission!$1:$998,5,0),"") | E56: =IFERROR(VLOOKUP($A56,Admission!$1:$998,3,0),"")
B57: =IFERROR(VLOOKUP($A57,Admission!$1:$998,4,0),"") | C57: =IFERROR(VLOOKUP($A57,Admission!$1:$998,5,0),"") | E57: =IFERROR(VLOOKUP($A57,Admission!$1:$998,3,0),"")
B58: =IFERROR(VLOOKUP($A58,Admission!$1:$998,4,0),"") | C58: =IFERROR(VLOOKUP($A58,Admission!$1:$998,5,0),"") | E58: =IFERROR(VLOOKUP($A58,Admission!$1:$998,3,0),"")
B59: =IFERROR(VLOOKUP($A59,Admission!$1:$998,4,0),"") | C59: =IFERROR(VLOOKUP($A59,Admission!$1:$998,5,0),"") | E59: =IFERROR(VLOOKUP($A59,Admission!$1:$998,3,0),"")
B60: =IFERROR(VLOOKUP($A60,Admission!$1:$998,4,0),"") | C60: =IFERROR(VLOOKUP($A60,Admission!$1:$998,5,0),"") | E60: =IFERROR(VLOOKUP($A60,Admission!$1:$998,3,0),"")
B61: =IFERROR(VLOOKUP($A61,Admission!$1:$998,4,0),"") | C61: =IFERROR(VLOOKUP($A61,Admission!$1:$998,5,0),"") | E61: =IFERROR(VLOOKUP($A61,Admission!$1:$998,3,0),"")
...

Sheet UKG
B1: Hosteller | C1: Day Scholar | E1: Overall Collection | F1: Monthly total fees collection
A2: =COUNT(A4:A358) -> 22 | B2: =COUNTIF($E$4:$E$184,B1) -> 17 | C2: =COUNTIF($E$4:$E$184,C1) -> 5 | E2: =SUM(F2:U2) -> 747600 | F2: =SUM(F$4:F$998) -> 21500 | G2: =SUM(G$4:G$998) -> 40000 | H2: =SUM(H$4:H$998) -> 62200 | I2: =SUM(I4:I24) -> 3000 | J2: =SUM(J$4:J$998) -> 65900 | K2: =SUM(K$4:K$998) -> 65900 | L2: =SUM(L$4:L$998) -> 65900 | M2: =SUM(M$4:M$998) -> 3600 | N2: =SUM(N$4:N$998) -> 69000 | O2: =SUM(O$4:O$998) -> 69000 | P2: =SUM(P$4:P$998) -> 69000 | Q2: =SUM(Q$4:Q$998) -> 3000 | ... U2: =SUM(U$4:U$998) -> 68600
A3: Ledger_No. | B3: Student_Name | C3: Father's name | D3: Phone No: | E3: Admission_Type | F3: Apr | G3: May | H3: Jun | I3: Exam | J3: Jul | K3: Aug | L3: Sep | M3: Exam Fee | N3: Oct | O3: Nov | P3: Dec | Q3: Exam Fee | R3: Jan | S3: Feb | T3: Exam Fee | U3: Mar
A4: 13 | B4: =IFERROR(VLOOKUP($A4,Admission!$1:$998,4,0),"") -> RASHID JAMAL | C4: =IFERROR(VLOOKUP($A4,Admission!$1:$998,5,0),"") -> IMTEYAZ AHMAD | D4: =IFERROR(VLOOKUP($A4,Admission!$1:$998,10,0),"") -> 7739447180 | E4: =IFERROR(VLOOKUP($A4,Admission!$1:$998,3,0),"") -> Hosteller | F4: 3700 | G4: 3700 | H4: 3700 | I4: 200 | J4: 3700 | K4: 3700 | L4: 3700 | M4: 200 | N4: 3700 | O4: 3700 | P4: 3700 | Q4: 200 | R4: 3700 | S4: 3700 | U4: 3700
A5: 15 | B5: =IFERROR(VLOOKUP($A5,Admission!$1:$998,4,0),"") -> WASI AHAMAD | C5: =IFERROR(VLOOKUP($A5,Admission!$1:$998,5,0),"") -> MD.MUKHTAR ANSARI | D5: =IFERROR(VLOOKUP($A5,Admission!$1:$998,10,0),"") -> 8809878555 | E5: =IFERROR(VLOOKUP($A5,Admission!$1:$998,3,0),"") -> Hosteller | F5: 3700 | G5: 3700 | H5: 3700 | I5: 200 | J5: 3700 | K5: 3700 | L5: 3700 | M5: 200 | N5: 3700 | O5: 3700 | P5: 3700 | Q5: 200 | R5: 3700 | S5: 3700 | T5: 200 | U5: 3700
A6: 21 | B6: =IFERROR(VLOOKUP($A6,Admission!$1:$998,4,0),"") -> SHAHBAJ ANSARI | C6: =IFERROR(VLOOKUP($A6,Admission!$1:$998,5,0),"") -> KALAM ANSARI | D6: =IFERROR(VLOOKUP($A6,Admission!$1:$998,10,0),"") -> 7667191848 | E6: =IFERROR(VLOOKUP($A6,Admission!$1:$998,3,0),"") -> Day Scholar | F6: 600 | G6: 600 | H6: 600 | I6: 200 | J6: 600 | K6: 600 | L6: 600 | M6: 200 | N6: 600 | O6: 600 | P6: 600 | Q6: 200 | R6: 600 | S6: 600 | T6: 200 | U6: 600
A7: 22 | B7: =IFERROR(VLOOKUP($A7,Admission!$1:$998,4,0),"") -> MD SAFID | C7: =IFERROR(VLOOKUP($A7,Admission!$1:$998,5,0),"") -> MD SAMSUL HAQUE | D7: =IFERROR(VLOOKUP($A7,Admission!$1:$998,10,0),"") -> 9955449861 | E7: =IFERROR(VLOOKUP($A7,Admission!$1:$998,3,0),"") -> Hosteller | F7: 3700 | G7: 3700 | H7: 3700 | J7: 3700 | K7: 3700 | L7: 3700 | N7: 3700 | O7: 3700 | P7: 3700 | R7: 3700 | S7: 3700 | U7: 3700
A8: 38 | B8: =IFERROR(VLOOKUP($A8,Admission!$1:$998,4,0),"") -> ZAKE AHMAD MOMIN | C8: =IFERROR(VLOOKUP($A8,Admission!$1:$998,5,0),"") -> ANISUR RAHMAN MOMIN | D8: =IFERROR(VLOOKUP($A8,Admission!$1:$998,10,0),"") -> 9883118912 | E8: =IFERROR(VLOOKUP($A8,Admission!$1:$998,3,0),"") -> Hosteller | F8: 3700 | G8: 3700 | H8: 3700 | I8: 200 | J8: 3700 | K8: 3700 | L8: 3700 | M8: 200 | N8: 3700 | O8: 3700 | P8: 3700 | Q8: 200 | R8: 3700 | S8: 3700 | T8: 200 | U8: 3700
A9: 46 | B9: =IFERROR(VLOOKUP($A9,Admission!$1:$998,4,0),"") -> ATIFA NAAZ | C9: =IFERROR(VLOOKUP($A9,Admission!$1:$998,5,0),"") -> TARIQUE ANWAR | D9: =IFERROR(VLOOKUP($A9,Admission!$1:$998,10,0),"") -> 8271818964 | E9: =IFERROR(VLOOKUP($A9,Admission!$1:$998,3,0),"") -> Day Scholar | F9: 600 | G9: 600 | H9: 600 | I9: 200 | J9: 600 | K9: 600 | L9: 600 | M9: 200 | N9: 600 | O9: 600 | P9: 600 | Q9: 200 | R9: 600 | S9: 600 | T9: 200 | U9: 200
A10: 87 | B10: =IFERROR(VLOOKUP($A10,Admission!$1:$998,4,0),"") -> JAMELA KHATUN | C10: =IFERROR(VLOOKUP($A10,Admission!$1:$998,5,0),"") -> RAMJAN ANSARI | D10: =IFERROR(VLOOKUP($A10,Admission!$1:$998,10,0),"") -> 8777097447 | E10: =IFERROR(VLOOKUP($A10,Admission!$1:$998,3,0),"") -> Hosteller | F10: 0 | G10: 3700 | H10: 3700 | I10: 150 | J10: 3700 | K10: 3700 | L10: 3700 | M10: 200 | N10: 3700 | O10: 3700 | P10: 3700 | Q10: 200 | R10: 3700 | S10: 3700 | T10: 200 | U10: 3700
A11: 88 | B11: =IFERROR(VLOOKUP($A11,Admission!$1:$998,4,0),"") -> ASHARAF ANSARI | C11: =IFERROR(VLOOKUP($A11,Admission!$1:$998,5,0),"") -> IMAMUDIN ANSARI | D11: =IFERROR(VLOOKUP($A11,Admission!$1:$998,10,0),"") -> 8777097447 | E11: =IFERROR(VLOOKUP($A11,Admission!$1:$998,3,0),"") -> Hosteller | F11: 0 | G11: 3700 | H11: 3700 | I11: 150 | J11: 3700 | K11: 3700 | L11: 3700 | M11: 200 | N11: 3700 | O11: 3700 | P11: 3700 | Q11: 200 | R11: 3700 | S11: 3700 | T11: 200 | U11: 3700
A12: 95 | B12: MD SAMIM ANSARI | C12: TOFIK ANSARI | D12: 8821258796 | E12: =IFERROR(VLOOKUP($A12,Admission!$1:$998,3,0),"") -> Hosteller | F12: 0 | G12: 3700 | H12: 3700 | I12: 150 | J12: 3700 | K12: 3700 | L12: 3700 | M12: 200 | N12: 3700 | O12: 3700 | P12: 3700 | R12: 3700 | S12: 3700 | T12: 200 | U12: 3700
A13: 103 | B13: =IFERROR(VLOOKUP($A13,Admission!$1:$998,4,0),"") -> SAFIK ANSARI | C13: =IFERROR(VLOOKUP($A13,Admission!$1:$998,5,0),"") -> NUR HUSEN | D13: =IFERROR(VLOOKUP($A13,Admission!$1:$998,10,0),"") -> 8797884145 | E13: =IFERROR(VLOOKUP($A13,Admission!$1:$998,3,0),"") -> Hosteller | F13: 0 | G13: 3700 | H13: 3700 | J13: 3700 | K13: 3700 | L13: 3700 | N13: 3700 | O13: 3700 | P13: 3700 | R13: 3700 | S13: 3700 | U13: 3700
A14: 112 | B14: =IFERROR(VLOOKUP($A14,Admission!$1:$998,4,0),"") -> MD ATIF SAHAL | C14: =IFERROR(VLOOKUP($A14,Admission!$1:$998,5,0),"") -> MD AMJAAD ANSARI | D14: =IFERROR(VLOOKUP($A14,Admission!$1:$998,10,0),"") -> 9771026583 | E14: =IFERROR(VLOOKUP($A14,Admission!$1:$998,3,0),"") -> Hosteller | F14: 0 | G14: 3700 | H14: 3700 | I14: 200 | J14: 3700 | K14: 3700 | L14: 3700 | M14: 200 | N14: 3700 | O14: 3700 | P14: 3700 | Q14: 200 | R14: 3700 | S14: 3700 | T14: 200 | U14: 3700
A15: 133 | B15: =IFERROR(VLOOKUP($A15,Admission!$1:$998,4,0),"") -> MARJIYA PARVEEN | C15: =IFERROR(VLOOKUP($A15,Admission!$1:$998,5,0),"") -> ABDUL KHABIR | D15: =IFERROR(VLOOKUP($A15,Admission!$1:$998,10,0),"") -> 9572384523 | E15: =IFERROR(VLOOKUP($A15,Admission!$1:$998,3,0),"") -> Hosteller | F15: 3700 | G15: 3700 | H15: 3700 | J15: 3700 | K15: 3700 | L15: 3700 | N15: 3700 | O15: 3700 | P15: 3700 | R15: 3700 | S15: 3700 | U15: 3700
A16: 149 | B16: =IFERROR(VLOOKUP($A16,Admission!$1:$998,4,0),"") -> TUHINA KHATUN | C16: =IFERROR(VLOOKUP($A16,Admission!$1:$998,5,0),"") -> RUHUL SHEKH | D16: =IFERROR(VLOOKUP($A16,Admission!$1:$998,10,0),"") -> 8210692094 | E16: =IFERROR(VLOOKUP($A16,Admission!$1:$998,3,0),"") -> Hosteller | F16: 0 | G16: 0 | H16: 3700 | I16: 200 | J16: 3700 | K16: 3700 | L16: 3700 | M16: 200 | N16: 3700 | O16: 3700 | P16: 3700 | Q16: 200 | R16: 3700 | S16: 3700 | T16: 200 | U16: 3700
A17: 151 | B17: =IFERROR(VLOOKUP($A17,Admission!$1:$998,4,0),"") -> NASHRIN KHATUN | C17: =IFERROR(VLOOKUP($A17,Admission!$1:$998,5,0),"") -> MD MANSUR SHEKH | D17: =IFERROR(VLOOKUP($A17,Admission!$1:$998,10,0),"") -> 9060522417 | E17: =IFERROR(VLOOKUP($A17,Admission!$1:$998,3,0),"") -> Hosteller | F17: 0 | G17: 0 | H17: 3700 | I17: 200 | J17: 3700 | K17: 3700 | L17: 3700 | M17: 200 | N17: 3700 | O17: 3700 | P17: 3700 | Q17: 200 | R17: 3700 | S17: 3700 | T17: 200 | U17: 3700
A18: 153 | B18: =IFERROR(VLOOKUP($A18,Admission!$1:$998,4,0),"") -> SHAHNAWAJ HUSSAIN | C18: =IFERROR(VLOOKUP($A18,Admission!$1:$998,5,0),"") -> MD SADDAM HUSSAIN | D18: =IFERROR(VLOOKUP($A18,Admission!$1:$998,10,0),"") -> 9980324610 | E18: =IFERROR(VLOOKUP($A18,Admission!$1:$998,3,0),"") -> Hosteller | F18: 0 | G18: 0 | H18: 3700 | J18: 3700 | K18: 3700 | L18: 3700 | M18: 200 | N18: 3700 | O18: 3700 | P18: 3700 | Q18: 200 | R18: 3700 | S18: 3700 | T18: 200 | U18: 3700
A19: 164 | B19: =IFERROR(VLOOKUP($A19,Admission!$1:$998,4,0),"") -> NAJMI ALAM | C19: =IFERROR(VLOOKUP($A19,Admission!$1:$998,5,0),"") -> APTARUL SHAIKH | D19: =IFERROR(VLOOKUP($A19,Admission!$1:$998,10,0),"") -> 6200832993 | E19: =IFERROR(VLOOKUP($A19,Admission!$1:$998,3,0),"") -> Hosteller | F19: 0 | G19: 0 | H19: 3700 | I19: 200 | J19: 3700 | K19: 3700 | L19: 3700 | M19: 200 | N19: 3700 | O19: 3700 | P19: 3700 | Q19: 200 | R19: 3700 | S19: 3700 | T19: 200 | U19: 3700
A20: 165 | B20: =IFERROR(VLOOKUP($A20,Admission!$1:$998,4,0),"") -> AYAN RAHMAN | C20: =IFERROR(VLOOKUP($A20,Admission!$1:$998,5,0),"") -> OBAIDUR RAHMAN | D20: =IFERROR(VLOOKUP($A20,Admission!$1:$998,10,0),"") -> 8340523933 | E20: =IFERROR(VLOOKUP($A20,Admission!$1:$998,3,0),"") -> Hosteller | F20: 0 | G20: 0 | H20: 3700 | I20: 200 | J20: 3700 | K20: 3700 | L20: 3700 | M20: 200 | N20: 3700 | O20: 3700 | P20: 3700 | Q20: 200 | R20: 3700 | S20: 3700 | T20: 200 | U20: 3700
A21: 167 | B21: =IFERROR(VLOOKUP($A21,Admission!$1:$998,4,0),"") -> ATIK ALAM | C21: =IFERROR(VLOOKUP($A21,Admission!$1:$998,5,0),"") -> ATABUL SHAIKH | D21: =IFERROR(VLOOKUP($A21,Admission!$1:$998,10,0),"") -> 6201046143 | E21: =IFERROR(VLOOKUP($A21,Admission!$1:$998,3,0),"") -> Hosteller | F21: 0 | G21: 0 | H21: 3700 | J21: 3700 | K21: 3700 | L21: 3700 | N21: 3700 | O21: 3700 | P21: 3700 | R21: 3700 | S21: 3700 | U21: 3700
A22: 170 | B22: =IFERROR(VLOOKUP($A22,Admission!$1:$998,4,0),"") -> ASAD GANI | C22: =IFERROR(VLOOKUP($A22,Admission!$1:$998,5,0),"") -> ABDUL GANI | D22: =IFERROR(VLOOKUP($A22,Admission!$1:$998,10,0),"") -> 8521469562 | E22: =IFERROR(VLOOKUP($A22,Admission!$1:$998,3,0),"") -> Day Scholar | F22: 600 | G22: 600 | H22: 600 | I22: 200 | J22: 600 | K22: 600 | L22: 600 | M22: 200 | N22: 600 | O22: 600 | P22: 600 | Q22: 200 | R22: 600 | S22: 600 | T22: 200 | U22: 600
A23: 172 | B23: =IFERROR(VLOOKUP($A23,Admission!$1:$998,4,0),"") -> NAFISH AHMAD | C23: =IFERROR(VLOOKUP($A23,Admission!$1:$998,5,0),"") -> NASIM AHMAD | D23: =IFERROR(VLOOKUP($A23,Admission!$1:$998,10,0),"") -> 9431388244 | E23: =IFERROR(VLOOKUP($A23,Admission!$1:$998,3,0),"") -> Day Scholar | F23: 600 | G23: 600 | H23: 600 | I23: 200 | J23: 600 | K23: 600 | L23: 600 | M23: 200 | N23: 3700 | O23: 3700 | P23: 3700 | Q23: 200 | R23: 3700 | S23: 3700 | T23: 200 | U23: 3700
A24: 174 | B24: =IFERROR(VLOOKUP($A24,Admission!$1:$998,4,0),"") -> RAHNUMA KHATUN | C24: =IFERROR(VLOOKUP($A24,Admission!$1:$998,5,0),"") -> ABUL KASIM | D24: =IFERROR(VLOOKUP($A24,Admission!$1:$998,10,0),"") -> 8709903830 | E24: =IFERROR(VLOOKUP($A24,Admission!$1:$998,3,0),"") -> Day Scholar | F24: 600 | G24: 600 | H24: 600 | I24: 150 | J24: 600 | K24: 600 | L24: 600 | M24: 200 | N24: 600 | O24: 600 | P24: 600 | R24: 600 | S24: 600 | U24: 600
A25: 177 | B25: =IFERROR(VLOOKUP($A25,Admission!$1:$998,4,0),"") -> NABEEL ANSARI | C25: =IFERROR(VLOOKUP($A25,Admission!$1:$998,5,0),"") -> ABDUR RAQUIB | D25: =IFERROR(VLOOKUP($A25,Admission!$1:$998,10,0),"") -> 7250389312 | E25: =IFERROR(VLOOKUP($A25,Admission!$1:$998,3,0),"") -> Hosteller | F25: 0 | G25: 0 | H25: 0 | I25: 0 | J25: 3700 | K25: 3700 | L25: 3700 | M25: 200 | N25: 3700 | O25: 3700 | P25: 3700 | R25: 3700 | S25: 3700 | U25: 3700
B26: =IFERROR(VLOOKUP($A26,Admission!$1:$998,4,0),"") | C26: =IFERROR(VLOOKUP($A26,Admission!$1:$998,5,0),"") | D26: =IFERROR(VLOOKUP($A26,Admission!$1:$998,10,0),"") | E26: =IFERROR(VLOOKUP($A26,Admission!$1:$998,3,0),"")
B27: =IFERROR(VLOOKUP($A27,Admission!$1:$998,4,0),"") | C27: =IFERROR(VLOOKUP($A27,Admission!$1:$998,5,0),"") | D27: =IFERROR(VLOOKUP($A27,Admission!$1:$998,10,0),"") | E27: =IFERROR(VLOOKUP($A27,Admission!$1:$998,3,0),"")
B28: =IFERROR(VLOOKUP($A28,Admission!$1:$998,4,0),"") | C28: =IFERROR(VLOOKUP($A28,Admission!$1:$998,5,0),"") | D28: =IFERROR(VLOOKUP($A28,Admission!$1:$998,10,0),"") | E28: =IFERROR(VLOOKUP($A28,Admission!$1:$998,3,0),"")
B29: =IFERROR(VLOOKUP($A29,Admission!$1:$998,4,0),"") | C29: =IFERROR(VLOOKUP($A29,Admission!$1:$998,5,0),"") | D29: =IFERROR(VLOOKUP($A29,Admission!$1:$998,10,0),"") | E29: =IFERROR(VLOOKUP($A29,Admission!$1:$998,3,0),"")
B30: =IFERROR(VLOOKUP($A30,Admission!$1:$998,4,0),"") | C30: =IFERROR(VLOOKUP($A30,Admission!$1:$998,5,0),"") | D30: =IFERROR(VLOOKUP($A30,Admission!$1:$998,10,0),"") | E30: =IFERROR(VLOOKUP($A30,Admission!$1:$998,3,0),"")
B31: =IFERROR(VLOOKUP($A31,Admission!$1:$998,4,0),"") | C31: =IFERROR(VLOOKUP($A31,Admission!$1:$998,5,0),"") | D31: =IFERROR(VLOOKUP($A31,Admission!$1:$998,10,0),"") | E31: =IFERROR(VLOOKUP($A31,Admission!$1:$998,3,0),"")
B32: =IFERROR(VLOOKUP($A32,Admission!$1:$998,4,0),"") | C32: =IFERROR(VLOOKUP($A32,Admission!$1:$998,5,0),"") | D32: =IFERROR(VLOOKUP($A32,Admission!$1:$998,10,0),"") | E32: =IFERROR(VLOOKUP($A32,Admission!$1:$998,3,0),"")
B33: =IFERROR(VLOOKUP($A33,Admission!$1:$998,4,0),"") | C33: =IFERROR(VLOOKUP($A33,Admission!$1:$998,5,0),"") | D33: =IFERROR(VLOOKUP($A33,Admission!$1:$998,10,0),"") | E33: =IFERROR(VLOOKUP($A33,Admission!$1:$998,3,0),"")
B34: =IFERROR(VLOOKUP($A34,Admission!$1:$998,4,0),"") | C34: =IFERROR(VLOOKUP($A34,Admission!$1:$998,5,0),"") | D34: =IFERROR(VLOOKUP($A34,Admission!$1:$998,10,0),"") | E34: =IFERROR(VLOOKUP($A34,Admission!$1:$998,3,0),"")
B35: =IFERROR(VLOOKUP($A35,Admission!$1:$998,4,0),"") | C35: =IFERROR(VLOOKUP($A35,Admission!$1:$998,5,0),"") | D35: =IFERROR(VLOOKUP($A35,Admission!$1:$998,10,0),"") | E35: =IFERROR(VLOOKUP($A35,Admission!$1:$998,3,0),"")
B36: =IFERROR(VLOOKUP($A36,Admission!$1:$998,4,0),"") | C36: =IFERROR(VLOOKUP($A36,Admission!$1:$998,5,0),"") | E36: =IFERROR(VLOOKUP($A36,Admission!$1:$998,3,0),"")
B37: =IFERROR(VLOOKUP($A37,Admission!$1:$998,4,0),"") | C37: =IFERROR(VLOOKUP($A37,Admission!$1:$998,5,0),"") | E37: =IFERROR(VLOOKUP($A37,Admission!$1:$998,3,0),"")
B38: =IFERROR(VLOOKUP($A38,Admission!$1:$998,4,0),"") | C38: =IFERROR(VLOOKUP($A38,Admission!$1:$998,5,0),"") | E38: =IFERROR(VLOOKUP($A38,Admission!$1:$998,3,0),"")
B39: =IFERROR(VLOOKUP($A39,Admission!$1:$998,4,0),"") | C39: =IFERROR(VLOOKUP($A39,Admission!$1:$998,5,0),"") | E39: =IFERROR(VLOOKUP($A39,Admission!$1:$998,3,0),"")
B40: =IFERROR(VLOOKUP($A40,Admission!$1:$998,4,0),"") | C40: =IFERROR(VLOOKUP($A40,Admission!$1:$998,5,0),"") | E40: =IFERROR(VLOOKUP($A40,Admission!$1:$998,3,0),"")
...

Sheet I
A1: s | B1: Hosteller | C1: Day Scholar | E1: Overall Collection | F1: Monthly total fees collection
A2: =COUNT(A4:A365) -> 31 | B2: =COUNTIF($E$4:$E$191,B1) -> 17 | C2: =COUNTIF($E$4:$E$191,C1) -> 14 | E2: =SUM(F2:U2) -> 733900 | F2: =SUM(F$4:F$1001) -> 52100 | G2: =SUM(G$4:G$1001) -> 56500 | H2: =SUM(H$4:H$1001) -> 67000 | I2: =SUM(I4:I34) -> 4300 | J2: =SUM(J$4:J$1001) -> 67000 | K2: =SUM(K$4:K$1001) -> 67000 | L2: =SUM(L$4:L$1001) -> 67000 | M2: =SUM(M$4:M$1001) -> 4200 | N2: =SUM(N$4:N$1001) -> 60200 | O2: =SUM(O$4:O$1001) -> 59600 | P2: =SUM(P$4:P$1001) -> 55900 | Q2: =SUM(Q$4:Q$1001) -> 3400 | ... U2: =SUM(U$4:U$1001) -> 55300
A3: Ledger_No. | B3: Student_Name | C3: Father's name | D3: Phone No: | E3: Admission_Type | F3: Apr | G3: May | H3: Jun | I3: Eame | J3: Jul | K3: Aug | L3: Sep | M3: Exam Fee | N3: Oct | O3: Nov | P3: Dec | Q3: Exam Fee | R3: Jan | S3: Feb | T3: Exam Fee | U3: Mar
A4: 3 | B4: =IFERROR(VLOOKUP($A4,Admission!$1:$998,4,0),"") -> TANISHA NAJ | C4: =IFERROR(VLOOKUP($A4,Admission!$1:$998,5,0),"") -> MD JARRAR HUSSAIN | D4: =IFERROR(VLOOKUP($A4,Admission!$1:$998,10,0),"") -> 7654919187 | E4: =IFERROR(VLOOKUP($A4,Admission!$1:$998,3,0),"") -> Day Scholar | F4: 600 | G4: 600 | H4: 600 | J4: 600 | K4: 600 | L4: 600 | N4: 600 | O4: left | P4: left | Q4: left | R4: left | S4: left | T4: left | U4: left
A5: 5 | B5: =IFERROR(VLOOKUP($A5,Admission!$1:$998,4,0),"") -> ARHAAN HAQUE | C5: =IFERROR(VLOOKUP($A5,Admission!$1:$998,5,0),"") -> IZAJUL HAQUE | D5: =IFERROR(VLOOKUP($A5,Admission!$1:$998,10,0),"") -> 9507760994 | E5: =IFERROR(VLOOKUP($A5,Admission!$1:$998,3,0),"") -> Day Scholar | F5: 600 | G5: 600 | H5: 600 | I5: 200 | J5: 600 | K5: 600 | L5: 600 | M5: 200 | N5: 600 | O5: 600 | P5: 600 | R5: 600 | S5: left | T5: left | U5: left
A6: 7 | B6: =IFERROR(VLOOKUP($A6,Admission!$1:$998,4,0),"") -> PARWEJ ISLAM | C6: =IFERROR(VLOOKUP($A6,Admission!$1:$998,5,0),"") -> RAFIKUL ISLAM | D6: =IFERROR(VLOOKUP($A6,Admission!$1:$998,10,0),"") -> 9142128216 | E6: =IFERROR(VLOOKUP($A6,Admission!$1:$998,3,0),"") -> Hosteller | F6: 3700 | G6: 3700 | H6: 3700 | J6: 3700 | K6: 3700 | L6: 3700 | N6: 3700 | O6: 3700 | P6: 3700 | R6: 3700 | S6: 3700 | U6: 3700
A7: 19 | B7: =IFERROR(VLOOKUP($A7,Admission!$1:$998,4,0),"") -> SIRAJ AHMAD | C7: =IFERROR(VLOOKUP($A7,Admission!$1:$998,5,0),"") -> KHUSHIRUDDIN SHEKH | D7: =IFERROR(VLOOKUP($A7,Admission!$1:$998,10,0),"") -> 9386044411 | E7: =IFERROR(VLOOKUP($A7,Admission!$1:$998,3,0),"") -> Hosteller | F7: 3700 | G7: 3700 | H7: 3700 | I7: 200 | J7: 3700 | K7: 3700 | L7: 3700 | M7: 200 | N7: 3700 | O7: 3700 | P7: 3700 | Q7: 200 | R7: 3700 | S7: 3700 | T7: 200 | U7: 3700
A8: 20 | B8: =IFERROR(VLOOKUP($A8,Admission!$1:$998,4,0),"") -> NUSRAT KHATUN | C8: =IFERROR(VLOOKUP($A8,Admission!$1:$998,5,0),"") -> KALAM ANSARI | D8: =IFERROR(VLOOKUP($A8,Admission!$1:$998,10,0),"") -> 7667191848 | E8: =IFERROR(VLOOKUP($A8,Admission!$1:$998,3,0),"") -> Day Scholar | F8: 600 | G8: 600 | H8: 600 | I8: 200 | J8: 600 | K8: 600 | L8: 600 | M8: 200 | N8: 600 | O8: 600 | P8: 600 | Q8: 200 | R8: 600 | S8: 600 | T8: 200 | U8: 600
A9: 24 | B9: =IFERROR(VLOOKUP($A9,Admission!$1:$998,4,0),"") -> AZIZA ASLAMI | C9: =IFERROR(VLOOKUP($A9,Admission!$1:$998,5,0),"") -> ABDUL HAKIM | D9: =IFERROR(VLOOKUP($A9,Admission!$1:$998,10,0),"") -> 9631552396 | E9: =IFERROR(VLOOKUP($A9,Admission!$1:$998,3,0),"") -> Day Scholar | F9: 600 | G9: 600 | H9: 600 | I9: 200 | J9: 600 | K9: 600 | L9: 600 | M9: 200 | N9: 600 | O9: 600 | P9: 600 | Q9: 200 | R9: 600 | S9: 600 | T9: 200 | U9: 600
A10: 30 | B10: =IFERROR(VLOOKUP($A10,Admission!$1:$998,4,0),"") -> MD REHAN | C10: =IFERROR(VLOOKUP($A10,Admission!$1:$998,5,0),"") -> NASIUR RAHMAN | D10: =IFERROR(VLOOKUP($A10,Admission!$1:$998,10,0),"") -> 8969545954 | E10: =IFERROR(VLOOKUP($A10,Admission!$1:$998,3,0),"") -> Hosteller | F10: 600 | G10: 600 | H10: 3700 | I10: 200 | J10: 3700 | K10: 3700 | L10: 3700 | M10: 200 | N10: 600 | O10: 600 | P10: 600 | Q10: 200 | R10: 600 | S10: 600 | T10: 200 | U10: 600
A11: 37 | B11: =IFERROR(VLOOKUP($A11,Admission!$1:$998,4,0),"") -> SHAH JISAN | C11: =IFERROR(VLOOKUP($A11,Admission!$1:$998,5,0),"") -> RAFIK ALAM | D11: =IFERROR(VLOOKUP($A11,Admission!$1:$998,10,0),"") -> 9955943696 | E11: =IFERROR(VLOOKUP($A11,Admission!$1:$998,3,0),"") -> Day Scholar | F11: 600 | G11: 600 | H11: 600 | I11: 200 | J11: 600 | K11: 600 | L11: 600 | M11: 200 | N11: 600 | O11: 600 | P11: 600 | Q11: 200 | R11: 600 | S11: 600 | T11: 200 | U11: 600
A12: 40 | B12: =IFERROR(VLOOKUP($A12,Admission!$1:$998,4,0),"") -> NIMAT PARVEEN | C12: =IFERROR(VLOOKUP($A12,Admission!$1:$998,5,0),"") -> HAJIKUL ALAM | D12: =IFERROR(VLOOKUP($A12,Admission!$1:$998,10,0),"") -> 8084078810 | E12: =IFERROR(VLOOKUP($A12,Admission!$1:$998,3,0),"") -> Day Scholar | F12: 600 | G12: 600 | H12: 600 | I12: 200 | J12: 600 | K12: 600 | L12: 600 | M12: 200 | N12: 600 | O12: 600 | P12: 600 | Q12: 200 | R12: 600 | S12: 600 | T12: 200 | U12: 600
A13: 42 | B13: =IFERROR(VLOOKUP($A13,Admission!$1:$998,4,0),"") -> MAHDIYA SULTANA | C13: =IFERROR(VLOOKUP($A13,Admission!$1:$998,5,0),"") -> FAHIM AKHTAR | D13: =IFERROR(VLOOKUP($A13,Admission!$1:$998,10,0),"") -> 9932282091 | E13: =IFERROR(VLOOKUP($A13,Admission!$1:$998,3,0),"") -> Day Scholar | F13: 500 | G13: 600 | H13: 600 | I13: 200 | J13: 600 | K13: 600 | L13: 600 | M13: 200 | N13: 600 | O13: 600 | P13: 600 | Q13: 200 | R13: 600 | S13: 600 | T13: 200 | U13: 600
A14: 44 | B14: =IFERROR(VLOOKUP($A14,Admission!$1:$998,4,0),"") -> ISRAT KHATUN | C14: =IFERROR(VLOOKUP($A14,Admission!$1:$998,5,0),"") -> USMAN SHEKH | D14: =IFERROR(VLOOKUP($A14,Admission!$1:$998,10,0),"") -> 8292473552 | E14: =IFERROR(VLOOKUP($A14,Admission!$1:$998,3,0),"") -> Day Scholar | F14: 600 | G14: 600 | H14: 600 | I14: 200 | J14: 600 | K14: 600 | L14: 600 | M14: 200 | N14: 600 | O14: 600 | P14: 600 | Q14: 200 | R14: 600 | S14: 600 | T14: 200 | U14: 600
A15: 47 | B15: =IFERROR(VLOOKUP($A15,Admission!$1:$998,4,0),"") -> EHAN ISLAM | C15: =IFERROR(VLOOKUP($A15,Admission!$1:$998,5,0),"") -> ANIKUL ISLAM | D15: =IFERROR(VLOOKUP($A15,Admission!$1:$998,10,0),"") -> 9064803071 | E15: =IFERROR(VLOOKUP($A15,Admission!$1:$998,3,0),"") -> Day Scholar | F15: 600 | G15: 600 | H15: 600 | I15: 200 | J15: 600 | K15: 600 | L15: 600 | M15: 200 | N15: 600 | O15: 600 | P15: 600 | Q15: 200 | R15: 600 | S15: 600 | T15: 200 | U15: 600
A16: 48 | B16: =IFERROR(VLOOKUP($A16,Admission!$1:$998,4,0),"") -> SAHIDA PARWEEN | C16: =IFERROR(VLOOKUP($A16,Admission!$1:$998,5,0),"") -> JAMIRUL ISLAM | D16: =IFERROR(VLOOKUP($A16,Admission!$1:$998,10,0),"") -> 9661301181 | E16: =IFERROR(VLOOKUP($A16,Admission!$1:$998,3,0),"") -> Day Scholar | F16: 600 | G16: 600 | H16: 600 | J16: 600 | K16: 600 | L16: 600 | N16: 600 | O16: 600 | P16: 600 | R16: 600 | S16: 600 | U16: 600
A17: 53 | B17: =IFERROR(VLOOKUP($A17,Admission!$1:$998,4,0),"") -> ROSHHAK ANSARI | C17: =IFERROR(VLOOKUP($A17,Admission!$1:$998,5,0),"") -> ISRAIL ANSARI | D17: =IFERROR(VLOOKUP($A17,Admission!$1:$998,10,0),"") -> 9801331446 | E17: =IFERROR(VLOOKUP($A17,Admission!$1:$998,3,0),"") -> Hosteller | F17: 3700 | G17: 3700 | H17: 3700 | I17: 200 | J17: 3700 | K17: 3700 | L17: 3700 | M17: 200 | N17: 3700 | O17: 3700 | P17: 3700 | Q17: 200 | R17: 3700 | S17: 3700 | T17: 200 | U17: 3700
A18: 52 | B18: =IFERROR(VLOOKUP($A18,Admission!$1:$998,4,0),"") -> MIFTAHUL ISLAM | C18: =IFERROR(VLOOKUP($A18,Admission!$1:$998,5,0),"") -> MD ALAUDDIN | D18: =IFERROR(VLOOKUP($A18,Admission!$1:$998,10,0),"") -> 9955001819 | E18: =IFERROR(VLOOKUP($A18,Admission!$1:$998,3,0),"") -> Hosteller | F18: 3700 | G18: 3700 | H18: 3700 | I18: 200 | J18: 3700 | K18: 3700 | L18: 3700 | M18: 200 | N18: 3700 | O18: 3700 | P18: 3700 | R18: 3700 | S18: 3700 | U18: 3700
A19: 70 | B19: =IFERROR(VLOOKUP($A19,Admission!$1:$998,4,0),"") -> MD ADIL AZHAR | C19: =IFERROR(VLOOKUP($A19,Admission!$1:$998,5,0),"") -> MD ZIAUL HAQUE | D19: =IFERROR(VLOOKUP($A19,Admission!$1:$998,10,0),"") -> 8809983740 | E19: =IFERROR(VLOOKUP($A19,Admission!$1:$998,3,0),"") -> Hosteller | F19: 3700 | G19: 3700 | H19: 3700 | I19: 200 | J19: 3700 | K19: 3700 | L19: 3700 | M19: 200 | N19: 3700 | O19: 3700 | P19: 3700 | Q19: 200 | R19: 3700 | S19: 3700 | T19: 200 | U19: 3700
A20: 73 | B20: =IFERROR(VLOOKUP($A20,Admission!$1:$998,4,0),"") -> MD JAYED AKHTAT | C20: =IFERROR(VLOOKUP($A20,Admission!$1:$998,5,0),"") -> FEKARUL SHEKH | D20: =IFERROR(VLOOKUP($A20,Admission!$1:$998,10,0),"") -> 9534235548 | E20: =IFERROR(VLOOKUP($A20,Admission!$1:$998,3,0),"") -> Hosteller | F20: 3700 | G20: 3700 | H20: 3700 | I20: 200 | J20: 3700 | K20: 3700 | L20: 3700 | N20: 3700 | O20: 3700 | P20: 3700 | R20: 3700 | S20: 3700 | U20: 3700
A21: 75 | B21: =IFERROR(VLOOKUP($A21,Admission!$1:$998,4,0),"") -> MOHAMMAD FARHAN ANSARI | C21: =IFERROR(VLOOKUP($A21,Admission!$1:$998,5,0),"") -> MOHAMMAD JIYAUL ANSARI | D21: =IFERROR(VLOOKUP($A21,Admission!$1:$998,10,0),"") -> 8809023587 | E21: =IFERROR(VLOOKUP($A21,Admission!$1:$998,3,0),"") -> Hosteller | F21: 3700 | G21: 3700 | H21: 3700 | I21: 150 | J21: 3700 | K21: 3700 | L21: 3700 | M21: 200 | N21: 3700 | O21: 3700 | P21: 3700 | Q21: 200 | R21: 3700 | S21: 3700 | U21: 3700
A22: 81 | B22: =IFERROR(VLOOKUP($A22,Admission!$1:$998,4,0),"") -> MD MODDASSHIR | C22: =IFERROR(VLOOKUP($A22,Admission!$1:$998,5,0),"") -> MD MOJAMMEL HAQUE | D22: =IFERROR(VLOOKUP($A22,Admission!$1:$998,10,0),"") -> 8051005138 | E22: =IFERROR(VLOOKUP($A22,Admission!$1:$998,3,0),"") -> Hosteller | F22: 3700 | G22: 3700 | H22: 3700 | J22: 3700 | K22: 3700 | L22: 3700 | N22: left | O22: left | P22: left | R22: left | S22: left | T22: left | U22: left
A23: 85 | B23: =IFERROR(VLOOKUP($A23,Admission!$1:$998,4,0),"") -> MD ANAS | C23: =IFERROR(VLOOKUP($A23,Admission!$1:$998,5,0),"") -> MOTIUR RAHMAN | D23: =IFERROR(VLOOKUP($A23,Admission!$1:$998,10,0),"") -> 9801054651 | E23: =IFERROR(VLOOKUP($A23,Admission!$1:$998,3,0),"") -> Hosteller | F23: 0 | G23: 0 | H23: 3700 | I23: 150 | J23: 3700 | K23: 3700 | L23: 3700 | M23: 200 | N23: 3700 | O23: 3700 | P23: 3700 | R23: 3700 | S23: 3700 | T23: 200 | U23: 3700
A24: 91 | B24: =IFERROR(VLOOKUP($A24,Admission!$1:$998,4,0),"") -> SABA KARIM | C24: =IFERROR(VLOOKUP($A24,Admission!$1:$998,5,0),"") -> MD ASHTAK | D24: =IFERROR(VLOOKUP($A24,Admission!$1:$998,10,0),"") -> 9162959792 | E24: =IFERROR(VLOOKUP($A24,Admission!$1:$998,3,0),"") -> Day Scholar | F24: left | G24: left | H24: ieft | I24: left | J24: left | K24: left | L24: left | N24: left | O24: left | P24: left | Q24: left | R24: left | S24: left | T24: left | U24: left
A25: 101 | B25: =IFERROR(VLOOKUP($A25,Admission!$1:$998,4,0),"") -> MD JUBAYER | C25: =IFERROR(VLOOKUP($A25,Admission!$1:$998,5,0),"") -> S.K MOSTAKIM | D25: =IFERROR(VLOOKUP($A25,Admission!$1:$998,10,0),"") -> 7407845971 | E25: =IFERROR(VLOOKUP($A25,Admission!$1:$998,3,0),"") -> Day Scholar | F25: 0 | G25: 600 | H25: 600 | I25: 200 | J25: 600 | K25: 600 | L25: 600 | M25: 200 | N25: 600 | O25: 600 | P25: 600 | Q25: 200 | R25: 600 | S25: 600 | T25: 200 | U25: 600
A26: 110 | B26: =IFERROR(VLOOKUP($A26,Admission!$1:$998,4,0),"") -> SAAD GANI | C26: =IFERROR(VLOOKUP($A26,Admission!$1:$998,5,0),"") -> ABDUL GANI | D26: =IFERROR(VLOOKUP($A26,Admission!$1:$998,10,0),"") -> 8521469562 | E26: =IFERROR(VLOOKUP($A26,Admission!$1:$998,3,0),"") -> Day Scholar | F26: 600 | G26: 600 | H26: 600 | I26: 200 | J26: 600 | K26: 600 | L26: 600 | M26: 200 | N26: 600 | O26: 600 | P26: 600 | R26: 600 | S26: 600 | T26: 200 | U26: 600
A27: 115 | B27: =IFERROR(VLOOKUP($A27,Admission!$1:$998,4,0),"") -> MD DILNAWAZ ANSARI | C27: =IFERROR(VLOOKUP($A27,Admission!$1:$998,5,0),"") -> MD DILDAR ANSARI | D27: =IFERROR(VLOOKUP($A27,Admission!$1:$998,10,0),"") -> 6200725672 | E27: =IFERROR(VLOOKUP($A27,Admission!$1:$998,3,0),"") -> Hosteller | F27: 3700 | G27: 3700 | H27: 3700 | J27: 3700 | K27: 3700 | L27: 3700 | N27: 3700 | O27: 3700 | P27: 3700 | R27: 3700 | S27: 3700 | U27: 3700
A28: 116 | B28: =IFERROR(VLOOKUP($A28,Admission!$1:$998,4,0),"") -> MD NASHIR ANSARI | C28: =IFERROR(VLOOKUP($A28,Admission!$1:$998,5,0),"") -> MD DILDAR ANSARI | D28: =IFERROR(VLOOKUP($A28,Admission!$1:$998,10,0),"") -> 6200725672 | E28: =IFERROR(VLOOKUP($A28,Admission!$1:$998,3,0),"") -> Hosteller | F28: 3700 | G28: 3700 | H28: 3700 | J28: 3700 | K28: 3700 | L28: 3700 | N28: 3700 | O28: 3700 | P28: 3700 | R28: 3700 | S28: 3700 | U28: 3700
A29: 128 | B29: =IFERROR(VLOOKUP($A29,Admission!$1:$998,4,0),"") -> AMRIN NISHA | C29: =IFERROR(VLOOKUP($A29,Admission!$1:$998,5,0),"") -> FIROJ ALAM | D29: =IFERROR(VLOOKUP($A29,Admission!$1:$998,10,0),"") -> 0 | E29: =IFERROR(VLOOKUP($A29,Admission!$1:$998,3,0),"") -> Hosteller | F29: FREE | G29: FREE | H29: FREE | I29: free | J29: free | K29: free | L29: free | M29: free | N29: free | O29: free | P29: free | Q29: free | R29: free | S29: free | T29: free | U29: free
